Workbook
Name col_days: Setup!$F$22
Name col_last: Setup!$F$23
Name col_prompts: Setup!$F$20
Name col_s1: Setup!$F$24
Name col_s2: Setup!$F$25
Name col_s3: Setup!$F$26
Name col_s4: Setup!$F$27
Name col_s5: Setup!$F$28
Name col_s6: Setup!$F$29
Name col_s7: Setup!$F$30
Name col_s8: Setup!$F$31
Name col_user: Setup!$F$19
Name col_web: Setup!$F$21
Name cust_name: Setup!$C$6
Name depth_line: Setup!$C$37
Name freq_line: Setup!$C$36
Name nrows: Setup!$C$12
Name period_days: Setup!$C$7
Name refresh_date: Setup!$C$8
Name run_mode: Setup!$C$14

Sheet Start Here
B2: Copilot Adoption Audit - workbook
B4: Paste one Microsoft Copilot usage report export into the Paste Export tab. Everything else computes itself.
B6: Where the data comes from
B7: Report | C7: Microsoft Copilot usage report - the user-level table.
B8: Portal | C8: Microsoft 365 admin center - admin.microsoft.com
B9: Navigation | C9: Reports > Usage > Microsoft Copilot > Copilot > the Usage tab. If Reports is not in the navigation menu, choose Show all first.
B10: Period | C10: 7 / 28 / 90 / 180 days. Take 180 for a full read, or 90 if you are working at small-tenant thresholds. Do not use 7 or 28 - they show you noise and call it a trend.
B11: Role | C11: Reports Reader is sufficient. Not Global Administrator.
B12: Before exporting | C12: Scroll to the user-level table and choose Choose columns, then switch on everything. The default column set is not enough.
B13: What you take | C13: The Export button on the user-level table. One CSV, one row per licensed user.
B14: The wrong Export | C14: The ellipsis menu on each individual chart also offers an Export. That gives you the chart's aggregate, not the user detail, and it is the mistake almost everyone makes the first time. You want the Export on the table.
B15: How to use this workbook
B16: 1 | C16: Open the CSV. Select everything including the header row, and copy.
B17: 2 | C17: Paste at cell A1 of the Paste Export tab - headers included. Delete the three example rows first; they are there to show the expected shape.
B18: 3 | C18: Fill in the four yellow cells on Setup: customer name, report period in days, refresh date, and a mode override if you want one.
B19: 4 | C19: Check the column-detection block on Setup. Every line should read FOUND.
B20: 5 | C20: Read Segments. That is the deliverable. Analysis is the per-user working, Chart is the scatter, Book Ranking is the portfolio view.
B21: The two modes
B22: LARGE (60+ rows) | C22: Thresholds are this tenant's own medians - median active days and median prompts. The scatter chart is meaningful.
B23: SMALL (under 60) | C23: Thresholds are fixed: 9 active days, and 15 prompts per week across the period. A median computed on thirty rows moves when one person takes annual leave. Do not use the chart in this mode - read the ranked list on Analysis.
B24: Override | C24: Set Setup C7 to SMALL or LARGE to force a mode. Leave it blank to let the row count decide. Whichever mode produced the numbers is stamped on the Segments subtitle - it will be the first question anyone asks six months later.
B25: Three rules this workbook enforces for you
B26: n<5 suppression | C26: No percentage, median or rate is reported for any band with fewer than five people in it. Those cells read 'n<5 not reported'. The raw count is still shown.
B27: Zero-guarding | C27: Prompts per active day divides by a column that is legitimately zero, and a log axis cannot plot zero prompts. Rates are wrapped, plot depth is floored at 1, and the excluded count is stated on Setup and on the chart caption.
B28: Correlational only | C28: This measures where the tool has not been made useful yet. It does not measure effort, contribution, productivity or performance. Say that in the room before the table goes on the screen, every time.
B29: Legend
B30: Yellow fill | C30: Cells you edit. Everything else is a formula - do not overtype it.
B31: Blue text | C31: A typed value rather than a calculation.
B32: Green text | C32: A link to a result on another sheet in this workbook.
B33: Capacity | C33: 1,000 users. Every formula range runs to row 1001. To extend, select the last row of Analysis and Calc, fill down as far as you need, and widen the Setup, Segments and Chart ranges to match. Twenty tenants of a few hundred seats each fit as they are.
B34: Before you paste a customer's file anywhere | C34: This is employee data. Get written permission, leave Microsoft's anonymization on, and decide where the file lives and when it is destroyed before the first one lands.

Sheet Paste Export
A1: User name | B1: Display name | C1: Prompts submitted (any app) | D1: Copilot Chat (work) prompts submitted | E1: Copilot Chat (web) prompts submitted | F1: Active Days | G1: Last activity date (UTC) | H1: Last activity date of Teams Copilot (UTC) | I1: Last activity date of Word Copilot (UTC) | J1: Last activity date of Excel Copilot (UTC) | K1: Last activity date of PowerPoint Copilot (UTC) | L1: Last activity date of Outlook Copilot (UTC) | M1: Last activity date of OneNote Copilot (UTC) | N1: Last activity date of Loop Copilot (UTC) | O1: Last activity date of Copilot Chat (work) (UTC) | P1: Last activity date of Copilot Chat (web) (UTC) | Q1: Last activity date of Microsoft 365 App (UTC) | R1: Last activity date of Microsoft Edge (UTC)
A2: A1B2C3D4E5F60718 | B2: 9F8E7D6C5B4A3928 | C2: 612 | D2: 470 | E2: 142 | F2: 47 | G2: 2026-08-25 | H2: 2026-08-25 | I2: 2026-08-22 | J2: 2026-08-19 | K2: 2026-08-11 | L2: 2026-08-25 | M2: 2026-07-30 | N2: 2026-08-06 | O2: 2026-08-25 | P2: 2026-08-24 | Q2: 2026-08-25 | R2: 2026-08-21
A3: 11223344556677AA | B3: BBCCDDEEFF001122 | C3: 96 | D3: 88 | E3: 8 | F3: 31 | G3: 2026-08-24 | H3: 2026-08-24 | I3: 2026-08-18 | L3: 2026-08-24 | O3: 2026-08-24 | Q3: 2026-08-13
A4: DEADBEEF01234567 | B4: 0123456789ABCDEF | C4: 11 | D4: 6 | E4: 5 | F4: 3 | G4: 2026-06-12 | H4: 2026-06-12 | I4: 2026-05-28 | K4: 2026-05-21 | L4: 2026-06-02 | O4: 2026-06-12 | P4: 2026-06-11
C6: The three rows above are EXAMPLES ONLY - one heavy user, one middling, one drifting. Delete them before you paste a real export. Paste at A1, headers included.

Sheet Setup
B2: Setup
B3: Fill in the yellow cells. Everything else is a formula.
B5: 1 - Inputs
B6: Customer name | C6: Example Customer Ltd | E6: The name that appears on the Segments subtitle.
B7: Report period (days) | C7: 90 | E7: 7, 28, 90 or 180. Drives the SMALL-mode depth line.
B8: Report refresh date (UTC) | C8: 2026-08-26 | E8: Shown at the top of the usage report. Type it as text if you prefer.
B9: Mode override (SMALL / LARGE / blank) | E9: Leave blank to let the row count decide.
B11: 2 - Detected from the pasted data
B12: Rows detected | C12: =COUNTA('Paste Export'!A2:A1001) -> 3 | E12: COUNTA over the first column of the paste area. Capacity 1,000 rows.
B13: Automatic mode | C13: =IF(C12>=60,"LARGE","SMALL") -> SMALL | E13: Sixty rows is where a median stops moving when one person takes leave.
B14: Mode in use | C14: =IF(C9="",C13,UPPER(C9)) -> SMALL | E14: This is stamped on the Segments subtitle so the numbers are traceable.
B16: 3 - Column detection (by header text, never by position)
B17: Each line matches the exact Microsoft header string against row 1 of Paste Export. Nothing in this workbook refers to a column letter of the pasted data.
B18: Field | E18: Header text matched | F18: Column | G18: Status
B19: User | E19: User name | F19: =IFERROR(MATCH($E19,'Paste Export'!$A$1:$BZ$1,0),0) -> 1 | G19: =IF($F19=0,"NOT FOUND","FOUND") -> FOUND
B20: Prompts (depth axis) | E20: Prompts submitted (any app) | F20: =IFERROR(MATCH($E20,'Paste Export'!$A$1:$BZ$1,0),0) -> 3 | G20: =IF($F20=0,"NOT FOUND","FOUND") -> FOUND
B21: Web prompts | E21: Copilot Chat (web) prompts submitted | F21: =IFERROR(MATCH($E21,'Paste Export'!$A$1:$BZ$1,0),0) -> 5 | G21: =IF($F21=0,"NOT FOUND","FOUND") -> FOUND
B22: Active days (frequency axis) | E22: Active Days | F22: =IFERROR(MATCH($E22,'Paste Export'!$A$1:$BZ$1,0),0) -> 6 | G22: =IF($F22=0,"NOT FOUND","FOUND") -> FOUND
B23: Last activity | E23: Last activity date (UTC) | F23: =IFERROR(MATCH($E23,'Paste Export'!$A$1:$BZ$1,0),0) -> 7 | G23: =IF($F23=0,"NOT FOUND","FOUND") -> FOUND
B24: Surface 1 - Teams | E24: Last activity date of Teams Copilot (UTC) | F24: =IFERROR(MATCH($E24,'Paste Export'!$A$1:$BZ$1,0),0) -> 8 | G24: =IF($F24=0,"NOT FOUND","FOUND") -> FOUND
B25: Surface 2 - Word | E25: Last activity date of Word Copilot (UTC) | F25: =IFERROR(MATCH($E25,'Paste Export'!$A$1:$BZ$1,0),0) -> 9 | G25: =IF($F25=0,"NOT FOUND","FOUND") -> FOUND
B26: Surface 3 - Excel | E26: Last activity date of Excel Copilot (UTC) | F26: =IFERROR(MATCH($E26,'Paste Export'!$A$1:$BZ$1,0),0) -> 10 | G26: =IF($F26=0,"NOT FOUND","FOUND") -> FOUND
B27: Surface 4 - PowerPoint | E27: Last activity date of PowerPoint Copilot (UTC) | F27: =IFERROR(MATCH($E27,'Paste Export'!$A$1:$BZ$1,0),0) -> 11 | G27: =IF($F27=0,"NOT FOUND","FOUND") -> FOUND
B28: Surface 5 - Outlook | E28: Last activity date of Outlook Copilot (UTC) | F28: =IFERROR(MATCH($E28,'Paste Export'!$A$1:$BZ$1,0),0) -> 12 | G28: =IF($F28=0,"NOT FOUND","FOUND") -> FOUND
B29: Surface 6 - OneNote | E29: Last activity date of OneNote Copilot (UTC) | F29: =IFERROR(MATCH($E29,'Paste Export'!$A$1:$BZ$1,0),0) -> 13 | G29: =IF($F29=0,"NOT FOUND","FOUND") -> FOUND
B30: Surface 7 - Loop | E30: Last activity date of Loop Copilot (UTC) | F30: =IFERROR(MATCH($E30,'Paste Export'!$A$1:$BZ$1,0),0) -> 14 | G30: =IF($F30=0,"NOT FOUND","FOUND") -> FOUND
B31: Surface 8 - Microsoft 365 App | E31: Last activity date of Microsoft 365 App (UTC) | F31: =IFERROR(MATCH($E31,'Paste Export'!$A$1:$BZ$1,0),0) -> 17 | G31: =IF($F31=0,"NOT FOUND","FOUND") -> FOUND
B33: =IF(COUNTIF($F$19:$F$31,0)=0,"All 13 columns found.","MISSING COLUMNS - "&COUNTIF($F$19:$F$31,0)&" of 13. Check you exported the user table with all columns switched on, and that this is a v2 report. Version 1 has no prompt or active-day columns at all.") -> All 13 columns found.
B35: 4 - Thresholds
B36: Frequency line - active days | C36: =IF(run_mode="SMALL", 9, MEDIAN(INDEX('Paste Export'!$A$2:$BZ$1001,0,col_days))) -> 9 | E36: =IF(run_mode="SMALL","Fixed: active in 9 of the past 12 weeks.","This tenant's own median active days.") -> Fixed: active in 9 of the past 12 weeks.
B37: Depth line - prompts | C37: =IF(run_mode="SMALL", ROUND(15*(period_days/7),0), MEDIAN(INDEX('Paste Export'!$A$2:$BZ$1001,0,col_prompts))) -> 193 | E37: =IF(run_mode="SMALL","Fixed: 15 prompts per week across "&period_days&" days.","This tenant's own median prompts.") -> Fixed: 15 prompts per week across 90 days.
B38: Band mapping: high frequency + high depth = Embedded. High frequency + low depth = Loyal but shallow. Low frequency + high depth = Project-driven. Low + low = Drifting.
B40: 5 - Disclosure counters (say these out loud)
B41: Never-active users | C41: =SUM(Analysis!$L$2:$L$1001) -> 0 | E41: Zero prompts and zero active days. The most defensible number here.
B42: Excluded from the chart (zero prompts) | C42: =COUNTIF(Analysis!$D$2:$D$1001,0) -> 0 | E42: A log axis cannot render zero. These are plotted at 1 - state the count on the slide.
B43: Surfaces counted per user | C43: 8 | E43: Teams, Word, Excel, PowerPoint, Outlook, OneNote, Loop and the Microsoft 365 App. Edge and the two chat entry points are chat surfaces, not application surfaces, and are excluded from the count.

Sheet Analysis
A1: # | B1: User | C1: Active days | D1: Prompts | E1: Web prompts | F1: Prompts / active day | G1: Web share of prompts | H1: Surfaces touched | I1: Band | J1: Drifting split | K1: Plot depth | L1: Never active
A2: =ROW()-1 -> 1 | B2: =IF($A2>nrows,"",IF(col_user=0,"",INDEX('Paste Export'!$A$2:$BZ$1001,$A2,col_user))) -> A1B2C3D4E5F60718 | C2: =IF($A2>nrows,"",IF(col_days=0,0,N(INDEX('Paste Export'!$A$2:$BZ$1001,$A2,col_days)))) -> 47 | D2: =IF($A2>nrows,"",IF(col_prompts=0,0,N(INDEX('Paste Export'!$A$2:$BZ$1001,$A2,col_prompts)))) -> 612 | E2: =IF($A2>nrows,"",IF(col_web=0,0,N(INDEX('Paste Export'!$A$2:$BZ$1001,$A2,col_web)))) -> 142 | F2: =IF($A2>nrows,"",IFERROR($D2/$C2,0)) -> 13.021277 | G2: =IF($A2>nrows,"",IFERROR($E2/$D2,"")) -> 0.23202614 | H2: =IF($A2>nrows,"",IF(col_s1=0,0,--(LEN(INDEX('Paste Export'!$A$2:$BZ$1001,$A2,col_s1))>0))+IF(col_s2=0,0,--(LEN(INDEX('Paste Export'!$A$2:$BZ$1001,$A2,col_s2))>0))+IF(col_s3=0,0,--(LEN(INDEX('Paste Export'!$A$2:$BZ$1001,$A2,col_s3))>0))+IF(col_s4=0,0,--(LEN(INDEX('Paste Export'!$A$2:$BZ$1001,$A2,col_s4))>0))+IF(col_s5=0,0,--(LEN(INDEX('Paste Export'!$A$2:$BZ$1001,$A2,col_s5))>0))+IF(col_s6=0,0,--(LEN(INDEX('Paste Export'!$A$2:$BZ$1001,$A2,col_s6))>0))+IF(col_s7=0,0,--(LEN(INDEX('Paste Export'!$A$2:$BZ$1001,$A2,col_s7))>0))+IF(col_s8=0,0,--(LEN(INDEX('Paste Export'!$A$2:$BZ$1001,$A2,col_s8))>0))) -> 8 | I2: =IF($A2>nrows,"",IF($C2>=freq_line,IF($D2>=depth_line,"Embedded","Loyal but shallow"),IF($D2>=depth_line,"Project-driven","Drifting"))) -> Embedded | J2: =IF($A2>nrows,"",IF($I2="Drifting",IF($H2>=3,"tried and stopped","never started"),"")) | K2: =IF($A2>nrows,"",MAX($D2,1)) -> 612 | L2: =IF($A2>nrows,"",IF(AND($C2=0,$D2=0),1,0)) -> 0
A3: =ROW()-1 -> 2 | B3: =IF($A3>nrows,"",IF(col_user=0,"",INDEX('Paste Export'!$A$2:$BZ$1001,$A3,col_user))) -> 11223344556677AA | C3: =IF($A3>nrows,"",IF(col_days=0,0,N(INDEX('Paste Export'!$A$2:$BZ$1001,$A3,col_days)))) -> 31 | D3: =IF($A3>nrows,"",IF(col_prompts=0,0,N(INDEX('Paste Export'!$A$2:$BZ$1001,$A3,col_prompts)))) -> 96 | E3: =IF($A3>nrows,"",IF(col_web=0,0,N(INDEX('Paste Export'!$A$2:$BZ$1001,$A3,col_web)))) -> 8 | F3: =IF($A3>nrows,"",IFERROR($D3/$C3,0)) -> 3.0967742 | G3: =IF($A3>nrows,"",IFERROR($E3/$D3,"")) -> 0.083333333 | H3: =IF($A3>nrows,"",IF(col_s1=0,0,--(LEN(INDEX('Paste Export'!$A$2:$BZ$1001,$A3,col_s1))>0))+IF(col_s2=0,0,--(LEN(INDEX('Paste Export'!$A$2:$BZ$1001,$A3,col_s2))>0))+IF(col_s3=0,0,--(LEN(INDEX('Paste Export'!$A$2:$BZ$1001,$A3,col_s3))>0))+IF(col_s4=0,0,--(LEN(INDEX('Paste Export'!$A$2:$BZ$1001,$A3,col_s4))>0))+IF(col_s5=0,0,--(LEN(INDEX('Paste Export'!$A$2:$BZ$1001,$A3,col_s5))>0))+IF(col_s6=0,0,--(LEN(INDEX('Paste Export'!$A$2:$BZ$1001,$A3,col_s6))>0))+IF(col_s7=0,0,--(LEN(INDEX('Paste Export'!$A$2:$BZ$1001,$A3,col_s7))>0))+IF(col_s8=0,0,--(LEN(INDEX('Paste Export'!$A$2:$BZ$1001,$A3,col_s8))>0))) -> 4 | I3: =IF($A3>nrows,"",IF($C3>=freq_line,IF($D3>=depth_line,"Embedded","Loyal but shallow"),IF($D3>=depth_line,"Project-driven","Drifting"))) -> Loyal but shallow | J3: =IF($A3>nrows,"",IF($I3="Drifting",IF($H3>=3,"tried and stopped","never started"),"")) | K3: =IF($A3>nrows,"",MAX($D3,1)) -> 96 | L3: =IF($A3>nrows,"",IF(AND($C3=0,$D3=0),1,0)) -> 0
A4: =ROW()-1 -> 3 | B4: =IF($A4>nrows,"",IF(col_user=0,"",INDEX('Paste Export'!$A$2:$BZ$1001,$A4,col_user))) -> DEADBEEF01234567 | C4: =IF($A4>nrows,"",IF(col_days=0,0,N(INDEX('Paste Export'!$A$2:$BZ$1001,$A4,col_days)))) -> 3 | D4: =IF($A4>nrows,"",IF(col_prompts=0,0,N(INDEX('Paste Export'!$A$2:$BZ$1001,$A4,col_prompts)))) -> 11 | E4: =IF($A4>nrows,"",IF(col_web=0,0,N(INDEX('Paste Export'!$A$2:$BZ$1001,$A4,col_web)))) -> 5 | F4: =IF($A4>nrows,"",IFERROR($D4/$C4,0)) -> 3.6666667 | G4: =IF($A4>nrows,"",IFERROR($E4/$D4,"")) -> 0.45454545 | H4: =IF($A4>nrows,"",IF(col_s1=0,0,--(LEN(INDEX('Paste Export'!$A$2:$BZ$1001,$A4,col_s1))>0))+IF(col_s2=0,0,--(LEN(INDEX('Paste Export'!$A$2:$BZ$1001,$A4,col_s2))>0))+IF(col_s3=0,0,--(LEN(INDEX('Paste Export'!$A$2:$BZ$1001,$A4,col_s3))>0))+IF(col_s4=0,0,--(LEN(INDEX('Paste Export'!$A$2:$BZ$1001,$A4,col_s4))>0))+IF(col_s5=0,0,--(LEN(INDEX('Paste Export'!$A$2:$BZ$1001,$A4,col_s5))>0))+IF(col_s6=0,0,--(LEN(INDEX('Paste Export'!$A$2:$BZ$1001,$A4,col_s6))>0))+IF(col_s7=0,0,--(LEN(INDEX('Paste Export'!$A$2:$BZ$1001,$A4,col_s7))>0))+IF(col_s8=0,0,--(LEN(INDEX('Paste Export'!$A$2:$BZ$1001,$A4,col_s8))>0))) -> 4 | I4: =IF($A4>nrows,"",IF($C4>=freq_line,IF($D4>=depth_line,"Embedded","Loyal but shallow"),IF($D4>=depth_line,"Project-driven","Drifting"))) -> Drifting | J4: =IF($A4>nrows,"",IF($I4="Drifting",IF($H4>=3,"tried and stopped","never started"),"")) -> tried and stopped | K4: =IF($A4>nrows,"",MAX($D4,1)) -> 11 | L4: =IF($A4>nrows,"",IF(AND($C4=0,$D4=0),1,0)) -> 0
A5: =ROW()-1 -> 4 | B5: =IF($A5>nrows,"",IF(col_user=0,"",INDEX('Paste Export'!$A$2:$BZ$1001,$A5,col_user))) | C5: =IF($A5>nrows,"",IF(col_days=0,0,N(INDEX('Paste Export'!$A$2:$BZ$1001,$A5,col_days)))) | D5: =IF($A5>nrows,"",IF(col_prompts=0,0,N(INDEX('Paste Export'!$A$2:$BZ$1001,$A5,col_prompts)))) | E5: =IF($A5>nrows,"",IF(col_web=0,0,N(INDEX('Paste Export'!$A$2:$BZ$1001,$A5,col_web)))) | F5: =IF($A5>nrows,"",IFERROR($D5/$C5,0)) | G5: =IF($A5>nrows,"",IFERROR($E5/$D5,"")) | H5: =IF($A5>nrows,"",IF(col_s1=0,0,--(LEN(INDEX('Paste Export'!$A$2:$BZ$1001,$A5,col_s1))>0))+IF(col_s2=0,0,--(LEN(INDEX('Paste Export'!$A$2:$BZ$1001,$A5,col_s2))>0))+IF(col_s3=0,0,--(LEN(INDEX('Paste Export'!$A$2:$BZ$1001,$A5,col_s3))>0))+IF(col_s4=0,0,--(LEN(INDEX('Paste Export'!$A$2:$BZ$1001,$A5,col_s4))>0))+IF(col_s5=0,0,--(LEN(INDEX('Paste Export'!$A$2:$BZ$1001,$A5,col_s5))>0))+IF(col_s6=0,0,--(LEN(INDEX('Paste Export'!$A$2:$BZ$1001,$A5,col_s6))>0))+IF(col_s7=0,0,--(LEN(INDEX('Paste Export'!$A$2:$BZ$1001,$A5,col_s7))>0))+IF(col_s8=0,0,--(LEN(INDEX('Paste Export'!$A$2:$BZ$1001,$A5,col_s8))>0))) | I5: =IF($A5>nrows,"",IF($C5>=freq_line,IF($D5>=depth_line,"Embedded","Loyal but shallow"),IF($D5>=depth_line,"Project-driven","Drifting"))) | J5: =IF($A5>nrows,"",IF($I5="Drifting",IF($H5>=3,"tried and stopped","never started"),"")) | K5: =IF($A5>nrows,"",MAX($D5,1)) | L5: =IF($A5>nrows,"",IF(AND($C5=0,$D5=0),1,0))
A6: =ROW()-1 -> 5 | B6: =IF($A6>nrows,"",IF(col_user=0,"",INDEX('Paste Export'!$A$2:$BZ$1001,$A6,col_user))) | C6: =IF($A6>nrows,"",IF(col_days=0,0,N(INDEX('Paste Export'!$A$2:$BZ$1001,$A6,col_days)))) | D6: =IF($A6>nrows,"",IF(col_prompts=0,0,N(INDEX('Paste Export'!$A$2:$BZ$1001,$A6,col_prompts)))) | E6: =IF($A6>nrows,"",IF(col_web=0,0,N(INDEX('Paste Export'!$A$2:$BZ$1001,$A6,col_web)))) | F6: =IF($A6>nrows,"",IFERROR($D6/$C6,0)) | G6: =IF($A6>nrows,"",IFERROR($E6/$D6,"")) | H6: =IF($A6>nrows,"",IF(col_s1=0,0,--(LEN(INDEX('Paste Export'!$A$2:$BZ$1001,$A6,col_s1))>0))+IF(col_s2=0,0,--(LEN(INDEX('Paste Export'!$A$2:$BZ$1001,$A6,col_s2))>0))+IF(col_s3=0,0,--(LEN(INDEX('Paste Export'!$A$2:$BZ$1001,$A6,col_s3))>0))+IF(col_s4=0,0,--(LEN(INDEX('Paste Export'!$A$2:$BZ$1001,$A6,col_s4))>0))+IF(col_s5=0,0,--(LEN(INDEX('Paste Export'!$A$2:$BZ$1001,$A6,col_s5))>0))+IF(col_s6=0,0,--(LEN(INDEX('Paste Export'!$A$2:$BZ$1001,$A6,col_s6))>0))+IF(col_s7=0,0,--(LEN(INDEX('Paste Export'!$A$2:$BZ$1001,$A6,col_s7))>0))+IF(col_s8=0,0,--(LEN(INDEX('Paste Export'!$A$2:$BZ$1001,$A6,col_s8))>0))) | I6: =IF($A6>nrows,"",IF($C6>=freq_line,IF($D6>=depth_line,"Embedded","Loyal but shallow"),IF($D6>=depth_line,"Project-driven","Drifting"))) | J6: =IF($A6>nrows,"",IF($I6="Drifting",IF($H6>=3,"tried and stopped","never started"),"")) | K6: =IF($A6>nrows,"",MAX($D6,1)) | L6: =IF($A6>nrows,"",IF(AND($C6=0,$D6=0),1,0))
A7: =ROW()-1 -> 6 | B7: =IF($A7>nrows,"",IF(col_user=0,"",INDEX('Paste Export'!$A$2:$BZ$1001,$A7,col_user))) | C7: =IF($A7>nrows,"",IF(col_days=0,0,N(INDEX('Paste Export'!$A$2:$BZ$1001,$A7,col_days)))) | D7: =IF($A7>nrows,"",IF(col_prompts=0,0,N(INDEX('Paste Export'!$A$2:$BZ$1001,$A7,col_prompts)))) | E7: =IF($A7>nrows,"",IF(col_web=0,0,N(INDEX('Paste Export'!$A$2:$BZ$1001,$A7,col_web)))) | F7: =IF($A7>nrows,"",IFERROR($D7/$C7,0)) | G7: =IF($A7>nrows,"",IFERROR($E7/$D7,"")) | H7: =IF($A7>nrows,"",IF(col_s1=0,0,--(LEN(INDEX('Paste Export'!$A$2:$BZ$1001,$A7,col_s1))>0))+IF(col_s2=0,0,--(LEN(INDEX('Paste Export'!$A$2:$BZ$1001,$A7,col_s2))>0))+IF(col_s3=0,0,--(LEN(INDEX('Paste Export'!$A$2:$BZ$1001,$A7,col_s3))>0))+IF(col_s4=0,0,--(LEN(INDEX('Paste Export'!$A$2:$BZ$1001,$A7,col_s4))>0))+IF(col_s5=0,0,--(LEN(INDEX('Paste Export'!$A$2:$BZ$1001,$A7,col_s5))>0))+IF(col_s6=0,0,--(LEN(INDEX('Paste Export'!$A$2:$BZ$1001,$A7,col_s6))>0))+IF(col_s7=0,0,--(LEN(INDEX('Paste Export'!$A$2:$BZ$1001,$A7,col_s7))>0))+IF(col_s8=0,0,--(LEN(INDEX('Paste Export'!$A$2:$BZ$1001,$A7,col_s8))>0))) | I7: =IF($A7>nrows,"",IF($C7>=freq_line,IF($D7>=depth_line,"Embedded","Loyal but shallow"),IF($D7>=depth_line,"Project-driven","Drifting"))) | J7: =IF($A7>nrows,"",IF($I7="Drifting",IF($H7>=3,"tried and stopped","never started"),"")) | K7: =IF($A7>nrows,"",MAX($D7,1)) | L7: =IF($A7>nrows,"",IF(AND($C7=0,$D7=0),1,0))
A8: =ROW()-1 -> 7 | B8: =IF($A8>nrows,"",IF(col_user=0,"",INDEX('Paste Export'!$A$2:$BZ$1001,$A8,col_user))) | C8: =IF($A8>nrows,"",IF(col_days=0,0,N(INDEX('Paste Export'!$A$2:$BZ$1001,$A8,col_days)))) | D8: =IF($A8>nrows,"",IF(col_prompts=0,0,N(INDEX('Paste Export'!$A$2:$BZ$1001,$A8,col_prompts)))) | E8: =IF($A8>nrows,"",IF(col_web=0,0,N(INDEX('Paste Export'!$A$2:$BZ$1001,$A8,col_web)))) | F8: =IF($A8>nrows,"",IFERROR($D8/$C8,0)) | G8: =IF($A8>nrows,"",IFERROR($E8/$D8,"")) | H8: =IF($A8>nrows,"",IF(col_s1=0,0,--(LEN(INDEX('Paste Export'!$A$2:$BZ$1001,$A8,col_s1))>0))+IF(col_s2=0,0,--(LEN(INDEX('Paste Export'!$A$2:$BZ$1001,$A8,col_s2))>0))+IF(col_s3=0,0,--(LEN(INDEX('Paste Export'!$A$2:$BZ$1001,$A8,col_s3))>0))+IF(col_s4=0,0,--(LEN(INDEX('Paste Export'!$A$2:$BZ$1001,$A8,col_s4))>0))+IF(col_s5=0,0,--(LEN(INDEX('Paste Export'!$A$2:$BZ$1001,$A8,col_s5))>0))+IF(col_s6=0,0,--(LEN(INDEX('Paste Export'!$A$2:$BZ$1001,$A8,col_s6))>0))+IF(col_s7=0,0,--(LEN(INDEX('Paste Export'!$A$2:$BZ$1001,$A8,col_s7))>0))+IF(col_s8=0,0,--(LEN(INDEX('Paste Export'!$A$2:$BZ$1001,$A8,col_s8))>0))) | I8: =IF($A8>nrows,"",IF($C8>=freq_line,IF($D8>=depth_line,"Embedded","Loyal but shallow"),IF($D8>=depth_line,"Project-driven","Drifting"))) | J8: =IF($A8>nrows,"",IF($I8="Drifting",IF($H8>=3,"tried and stopped","never started"),"")) | K8: =IF($A8>nrows,"",MAX($D8,1)) | L8: =IF($A8>nrows,"",IF(AND($C8=0,$D8=0),1,0))
A9: =ROW()-1 -> 8 | B9: =IF($A9>nrows,"",IF(col_user=0,"",INDEX('Paste Export'!$A$2:$BZ$1001,$A9,col_user))) | C9: =IF($A9>nrows,"",IF(col_days=0,0,N(INDEX('Paste Export'!$A$2:$BZ$1001,$A9,col_days)))) | D9: =IF($A9>nrows,"",IF(col_prompts=0,0,N(INDEX('Paste Export'!$A$2:$BZ$1001,$A9,col_prompts)))) | E9: =IF($A9>nrows,"",IF(col_web=0,0,N(INDEX('Paste Export'!$A$2:$BZ$1001,$A9,col_web)))) | F9: =IF($A9>nrows,"",IFERROR($D9/$C9,0)) | G9: =IF($A9>nrows,"",IFERROR($E9/$D9,"")) | H9: =IF($A9>nrows,"",IF(col_s1=0,0,--(LEN(INDEX('Paste Export'!$A$2:$BZ$1001,$A9,col_s1))>0))+IF(col_s2=0,0,--(LEN(INDEX('Paste Export'!$A$2:$BZ$1001,$A9,col_s2))>0))+IF(col_s3=0,0,--(LEN(INDEX('Paste Export'!$A$2:$BZ$1001,$A9,col_s3))>0))+IF(col_s4=0,0,--(LEN(INDEX('Paste Export'!$A$2:$BZ$1001,$A9,col_s4))>0))+IF(col_s5=0,0,--(LEN(INDEX('Paste Export'!$A$2:$BZ$1001,$A9,col_s5))>0))+IF(col_s6=0,0,--(LEN(INDEX('Paste Export'!$A$2:$BZ$1001,$A9,col_s6))>0))+IF(col_s7=0,0,--(LEN(INDEX('Paste Export'!$A$2:$BZ$1001,$A9,col_s7))>0))+IF(col_s8=0,0,--(LEN(INDEX('Paste Export'!$A$2:$BZ$1001,$A9,col_s8))>0))) | I9: =IF($A9>nrows,"",IF($C9>=freq_line,IF($D9>=depth_line,"Embedded","Loyal but shallow"),IF($D9>=depth_line,"Project-driven","Drifting"))) | J9: =IF($A9>nrows,"",IF($I9="Drifting",IF($H9>=3,"tried and stopped","never started"),"")) | K9: =IF($A9>nrows,"",MAX($D9,1)) | L9: =IF($A9>nrows,"",IF(AND($C9=0,$D9=0),1,0))
A10: =ROW()-1 -> 9 | B10: =IF($A10>nrows,"",IF(col_user=0,"",INDEX('Paste Export'!$A$2:$BZ$1001,$A10,col_user))) | C10: =IF($A10>nrows,"",IF(col_days=0,0,N(INDEX('Paste Export'!$A$2:$BZ$1001,$A10,col_days)))) | D10: =IF($A10>nrows,"",IF(col_prompts=0,0,N(INDEX('Paste Export'!$A$2:$BZ$1001,$A10,col_prompts)))) | E10: =IF($A10>nrows,"",IF(col_web=0,0,N(INDEX('Paste Export'!$A$2:$BZ$1001,$A10,col_web)))) | F10: =IF($A10>nrows,"",IFERROR($D10/$C10,0)) | G10: =IF($A10>nrows,"",IFERROR($E10/$D10,"")) | H10: =IF($A10>nrows,"",IF(col_s1=0,0,--(LEN(INDEX('Paste Export'!$A$2:$BZ$1001,$A10,col_s1))>0))+IF(col_s2=0,0,--(LEN(INDEX('Paste Export'!$A$2:$BZ$1001,$A10,col_s2))>0))+IF(col_s3=0,0,--(LEN(INDEX('Paste Export'!$A$2:$BZ$1001,$A10,col_s3))>0))+IF(col_s4=0,0,--(LEN(INDEX('Paste Export'!$A$2:$BZ$1001,$A10,col_s4))>0))+IF(col_s5=0,0,--(LEN(INDEX('Paste Export'!$A$2:$BZ$1001,$A10,col_s5))>0))+IF(col_s6=0,0,--(LEN(INDEX('Paste Export'!$A$2:$BZ$1001,$A10,col_s6))>0))+IF(col_s7=0,0,--(LEN(INDEX('Paste Export'!$A$2:$BZ$1001,$A10,col_s7))>0))+IF(col_s8=0,0,--(LEN(INDEX('Paste Export'!$A$2:$BZ$1001,$A10,col_s8))>0))) | I10: =IF($A10>nrows,"",IF($C10>=freq_line,IF($D10>=depth_line,"Embedded","Loyal but shallow"),IF($D10>=depth_line,"Project-driven","Drifting"))) | J10: =IF($A10>nrows,"",IF($I10="Drifting",IF($H10>=3,"tried and stopped","never started"),"")) | K10: =IF($A10>nrows,"",MAX($D10,1)) | L10: =IF($A10>nrows,"",IF(AND($C10=0,$D10=0),1,0))
A11: =ROW()-1 -> 10 | B11: =IF($A11>nrows,"",IF(col_user=0,"",INDEX('Paste Export'!$A$2:$BZ$1001,$A11,col_user))) | C11: =IF($A11>nrows,"",IF(col_days=0,0,N(INDEX('Paste Export'!$A$2:$BZ$1001,$A11,col_days)))) | D11: =IF($A11>nrows,"",IF(col_prompts=0,0,N(INDEX('Paste Export'!$A$2:$BZ$1001,$A11,col_prompts)))) | E11: =IF($A11>nrows,"",IF(col_web=0,0,N(INDEX('Paste Export'!$A$2:$BZ$1001,$A11,col_web)))) | F11: =IF($A11>nrows,"",IFERROR($D11/$C11,0)) | G11: =IF($A11>nrows,"",IFERROR($E11/$D11,"")) | H11: =IF($A11>nrows,"",IF(col_s1=0,0,--(LEN(INDEX('Paste Export'!$A$2:$BZ$1001,$A11,col_s1))>0))+IF(col_s2=0,0,--(LEN(INDEX('Paste Export'!$A$2:$BZ$1001,$A11,col_s2))>0))+IF(col_s3=0,0,--(LEN(INDEX('Paste Export'!$A$2:$BZ$1001,$A11,col_s3))>0))+IF(col_s4=0,0,--(LEN(INDEX('Paste Export'!$A$2:$BZ$1001,$A11,col_s4))>0))+IF(col_s5=0,0,--(LEN(INDEX('Paste Export'!$A$2:$BZ$1001,$A11,col_s5))>0))+IF(col_s6=0,0,--(LEN(INDEX('Paste Export'!$A$2:$BZ$1001,$A11,col_s6))>0))+IF(col_s7=0,0,--(LEN(INDEX('Paste Export'!$A$2:$BZ$1001,$A11,col_s7))>0))+IF(col_s8=0,0,--(LEN(INDEX('Paste Export'!$A$2:$BZ$1001,$A11,col_s8))>0))) | I11: =IF($A11>nrows,"",IF($C11>=freq_line,IF($D11>=depth_line,"Embedded","Loyal but shallow"),IF($D11>=depth_line,"Project-driven","Drifting"))) | J11: =IF($A11>nrows,"",IF($I11="Drifting",IF($H11>=3,"tried and stopped","never started"),"")) | K11: =IF($A11>nrows,"",MAX($D11,1)) | L11: =IF($A11>nrows,"",IF(AND($C11=0,$D11=0),1,0))
A12: =ROW()-1 -> 11 | B12: =IF($A12>nrows,"",IF(col_user=0,"",INDEX('Paste Export'!$A$2:$BZ$1001,$A12,col_user))) | C12: =IF($A12>nrows,"",IF(col_days=0,0,N(INDEX('Paste Export'!$A$2:$BZ$1001,$A12,col_days)))) | D12: =IF($A12>nrows,"",IF(col_prompts=0,0,N(INDEX('Paste Export'!$A$2:$BZ$1001,$A12,col_prompts)))) | E12: =IF($A12>nrows,"",IF(col_web=0,0,N(INDEX('Paste Export'!$A$2:$BZ$1001,$A12,col_web)))) | F12: =IF($A12>nrows,"",IFERROR($D12/$C12,0)) | G12: =IF($A12>nrows,"",IFERROR($E12/$D12,"")) | H12: =IF($A12>nrows,"",IF(col_s1=0,0,--(LEN(INDEX('Paste Export'!$A$2:$BZ$1001,$A12,col_s1))>0))+IF(col_s2=0,0,--(LEN(INDEX('Paste Export'!$A$2:$BZ$1001,$A12,col_s2))>0))+IF(col_s3=0,0,--(LEN(INDEX('Paste Export'!$A$2:$BZ$1001,$A12,col_s3))>0))+IF(col_s4=0,0,--(LEN(INDEX('Paste Export'!$A$2:$BZ$1001,$A12,col_s4))>0))+IF(col_s5=0,0,--(LEN(INDEX('Paste Export'!$A$2:$BZ$1001,$A12,col_s5))>0))+IF(col_s6=0,0,--(LEN(INDEX('Paste Export'!$A$2:$BZ$1001,$A12,col_s6))>0))+IF(col_s7=0,0,--(LEN(INDEX('Paste Export'!$A$2:$BZ$1001,$A12,col_s7))>0))+IF(col_s8=0,0,--(LEN(INDEX('Paste Export'!$A$2:$BZ$1001,$A12,col_s8))>0))) | I12: =IF($A12>nrows,"",IF($C12>=freq_line,IF($D12>=depth_line,"Embedded","Loyal but shallow"),IF($D12>=depth_line,"Project-driven","Drifting"))) | J12: =IF($A12>nrows,"",IF($I12="Drifting",IF($H12>=3,"tried and stopped","never started"),"")) | K12: =IF($A12>nrows,"",MAX($D12,1)) | L12: =IF($A12>nrows,"",IF(AND($C12=0,$D12=0),1,0))
A13: =ROW()-1 -> 12 | B13: =IF($A13>nrows,"",IF(col_user=0,"",INDEX('Paste Export'!$A$2:$BZ$1001,$A13,col_user))) | C13: =IF($A13>nrows,"",IF(col_days=0,0,N(INDEX('Paste Export'!$A$2:$BZ$1001,$A13,col_days)))) | D13: =IF($A13>nrows,"",IF(col_prompts=0,0,N(INDEX('Paste Export'!$A$2:$BZ$1001,$A13,col_prompts)))) | E13: =IF($A13>nrows,"",IF(col_web=0,0,N(INDEX('Paste Export'!$A$2:$BZ$1001,$A13,col_web)))) | F13: =IF($A13>nrows,"",IFERROR($D13/$C13,0)) | G13: =IF($A13>nrows,"",IFERROR($E13/$D13,"")) | H13: =IF($A13>nrows,"",IF(col_s1=0,0,--(LEN(INDEX('Paste Export'!$A$2:$BZ$1001,$A13,col_s1))>0))+IF(col_s2=0,0,--(LEN(INDEX('Paste Export'!$A$2:$BZ$1001,$A13,col_s2))>0))+IF(col_s3=0,0,--(LEN(INDEX('Paste Export'!$A$2:$BZ$1001,$A13,col_s3))>0))+IF(col_s4=0,0,--(LEN(INDEX('Paste Export'!$A$2:$BZ$1001,$A13,col_s4))>0))+IF(col_s5=0,0,--(LEN(INDEX('Paste Export'!$A$2:$BZ$1001,$A13,col_s5))>0))+IF(col_s6=0,0,--(LEN(INDEX('Paste Export'!$A$2:$BZ$1001,$A13,col_s6))>0))+IF(col_s7=0,0,--(LEN(INDEX('Paste Export'!$A$2:$BZ$1001,$A13,col_s7))>0))+IF(col_s8=0,0,--(LEN(INDEX('Paste Export'!$A$2:$BZ$1001,$A13,col_s8))>0))) | I13: =IF($A13>nrows,"",IF($C13>=freq_line,IF($D13>=depth_line,"Embedded","Loyal but shallow"),IF($D13>=depth_line,"Project-driven","Drifting"))) | J13: =IF($A13>nrows,"",IF($I13="Drifting",IF($H13>=3,"tried and stopped","never started"),"")) | K13: =IF($A13>nrows,"",MAX($D13,1)) | L13: =IF($A13>nrows,"",IF(AND($C13=0,$D13=0),1,0))
... A1001: =ROW()-1 -> 1000 | B1001: =IF($A1001>nrows,"",IF(col_user=0,"",INDEX('Paste Export'!$A$2:$BZ$1001,$A1001,col_user))) | C1001: =IF($A1001>nrows,"",IF(col_days=0,0,N(INDEX('Paste Export'!$A$2:$BZ$1001,$A1001,col_days)))) | D1001: =IF($A1001>nrows,"",IF(col_prompts=0,0,N(INDEX('Paste Export'!$A$2:$BZ$1001,$A1001,col_prompts)))) | E1001: =IF($A1001>nrows,"",IF(col_web=0,0,N(INDEX('Paste Export'!$A$2:$BZ$1001,$A1001,col_web)))) | F1001: =IF($A1001>nrows,"",IFERROR($D1001/$C1001,0)) | G1001: =IF($A1001>nrows,"",IFERROR($E1001/$D1001,"")) | H1001: =IF($A1001>nrows,"",IF(col_s1=0,0,--(LEN(INDEX('Paste Export'!$A$2:$BZ$1001,$A1001,col_s1))>0))+IF(col_s2=0,0,--(LEN(INDEX('Paste Export'!$A$2:$BZ$1001,$A1001,col_s2))>0))+IF(col_s3=0,0,--(LEN(INDEX('Paste Export'!$A$2:$BZ$1001,$A1001,col_s3))>0))+IF(col_s4=0,0,--(LEN(INDEX('Paste Export'!$A$2:$BZ$1001,$A1001,col_s4))>0))+IF(col_s5=0,0,--(LEN(INDEX('Paste Export'!$A$2:$BZ$1001,$A1001,col_s5))>0))+IF(col_s6=0,0,--(LEN(INDEX('Paste Export'!$A$2:$BZ$1001,$A1001,col_s6))>0))+IF(col_s7=0,0,--(LEN(INDEX('Paste Export'!$A$2:$BZ$1001,$A1001,col_s7))>0))+IF(col_s8=0,0,--(LEN(INDEX('Paste Export'!$A$2:$BZ$1001,$A1001,col_s8))>0))) | I1001: =IF($A1001>nrows,"",IF($C1001>=freq_line,IF($D1001>=depth_line,"Embedded","Loyal but shallow"),IF($D1001>=depth_line,"Project-driven","Drifting"))) | J1001: =IF($A1001>nrows,"",IF($I1001="Drifting",IF($H1001>=3,"tried and stopped","never started"),"")) | K1001: =IF($A1001>nrows,"",MAX($D1001,1)) | L1001: =IF($A1001>nrows,"",IF(AND($C1001=0,$D1001=0),1,0))

Sheet Calc
A1: Embedded - Prompts | B1: Loyal but shallow - Prompts | C1: Project-driven - Prompts | D1: Drifting - Prompts | E1: Embedded - Active days | F1: Loyal but shallow - Active days | G1: Project-driven - Active days | H1: Drifting - Active days | I1: Embedded - Prompts / active day | J1: Loyal but shallow - Prompts / active day | K1: Project-driven - Prompts / active day | L1: Drifting - Prompts / active day | M1: Embedded - Surfaces | N1: Loyal but shallow - Surfaces | O1: Project-driven - Surfaces | P1: Drifting - Surfaces
A2: =IF(Analysis!$I2="","",IF(Analysis!$I2="Embedded",Analysis!$D2,"")) -> 612 | B2: =IF(Analysis!$I2="","",IF(Analysis!$I2="Loyal but shallow",Analysis!$D2,"")) | C2: =IF(Analysis!$I2="","",IF(Analysis!$I2="Project-driven",Analysis!$D2,"")) | D2: =IF(Analysis!$I2="","",IF(Analysis!$I2="Drifting",Analysis!$D2,"")) | E2: =IF(Analysis!$I2="","",IF(Analysis!$I2="Embedded",Analysis!$C2,"")) -> 47 | F2: =IF(Analysis!$I2="","",IF(Analysis!$I2="Loyal but shallow",Analysis!$C2,"")) | G2: =IF(Analysis!$I2="","",IF(Analysis!$I2="Project-driven",Analysis!$C2,"")) | H2: =IF(Analysis!$I2="","",IF(Analysis!$I2="Drifting",Analysis!$C2,"")) | I2: =IF(Analysis!$I2="","",IF(Analysis!$I2="Embedded",Analysis!$F2,"")) -> 13.021277 | J2: =IF(Analysis!$I2="","",IF(Analysis!$I2="Loyal but shallow",Analysis!$F2,"")) | K2: =IF(Analysis!$I2="","",IF(Analysis!$I2="Project-driven",Analysis!$F2,"")) | L2: =IF(Analysis!$I2="","",IF(Analysis!$I2="Drifting",Analysis!$F2,"")) | M2: =IF(Analysis!$I2="","",IF(Analysis!$I2="Embedded",Analysis!$H2,"")) -> 8 | N2: =IF(Analysis!$I2="","",IF(Analysis!$I2="Loyal but shallow",Analysis!$H2,"")) | O2: =IF(Analysis!$I2="","",IF(Analysis!$I2="Project-driven",Analysis!$H2,"")) | P2: =IF(Analysis!$I2="","",IF(Analysis!$I2="Drifting",Analysis!$H2,""))
A3: =IF(Analysis!$I3="","",IF(Analysis!$I3="Embedded",Analysis!$D3,"")) | B3: =IF(Analysis!$I3="","",IF(Analysis!$I3="Loyal but shallow",Analysis!$D3,"")) -> 96 | C3: =IF(Analysis!$I3="","",IF(Analysis!$I3="Project-driven",Analysis!$D3,"")) | D3: =IF(Analysis!$I3="","",IF(Analysis!$I3="Drifting",Analysis!$D3,"")) | E3: =IF(Analysis!$I3="","",IF(Analysis!$I3="Embedded",Analysis!$C3,"")) | F3: =IF(Analysis!$I3="","",IF(Analysis!$I3="Loyal but shallow",Analysis!$C3,"")) -> 31 | G3: =IF(Analysis!$I3="","",IF(Analysis!$I3="Project-driven",Analysis!$C3,"")) | H3: =IF(Analysis!$I3="","",IF(Analysis!$I3="Drifting",Analysis!$C3,"")) | I3: =IF(Analysis!$I3="","",IF(Analysis!$I3="Embedded",Analysis!$F3,"")) | J3: =IF(Analysis!$I3="","",IF(Analysis!$I3="Loyal but shallow",Analysis!$F3,"")) -> 3.0967742 | K3: =IF(Analysis!$I3="","",IF(Analysis!$I3="Project-driven",Analysis!$F3,"")) | L3: =IF(Analysis!$I3="","",IF(Analysis!$I3="Drifting",Analysis!$F3,"")) | M3: =IF(Analysis!$I3="","",IF(Analysis!$I3="Embedded",Analysis!$H3,"")) | N3: =IF(Analysis!$I3="","",IF(Analysis!$I3="Loyal but shallow",Analysis!$H3,"")) -> 4 | O3: =IF(Analysis!$I3="","",IF(Analysis!$I3="Project-driven",Analysis!$H3,"")) | P3: =IF(Analysis!$I3="","",IF(Analysis!$I3="Drifting",Analysis!$H3,""))
A4: =IF(Analysis!$I4="","",IF(Analysis!$I4="Embedded",Analysis!$D4,"")) | B4: =IF(Analysis!$I4="","",IF(Analysis!$I4="Loyal but shallow",Analysis!$D4,"")) | C4: =IF(Analysis!$I4="","",IF(Analysis!$I4="Project-driven",Analysis!$D4,"")) | D4: =IF(Analysis!$I4="","",IF(Analysis!$I4="Drifting",Analysis!$D4,"")) -> 11 | E4: =IF(Analysis!$I4="","",IF(Analysis!$I4="Embedded",Analysis!$C4,"")) | F4: =IF(Analysis!$I4="","",IF(Analysis!$I4="Loyal but shallow",Analysis!$C4,"")) | G4: =IF(Analysis!$I4="","",IF(Analysis!$I4="Project-driven",Analysis!$C4,"")) | H4: =IF(Analysis!$I4="","",IF(Analysis!$I4="Drifting",Analysis!$C4,"")) -> 3 | I4: =IF(Analysis!$I4="","",IF(Analysis!$I4="Embedded",Analysis!$F4,"")) | J4: =IF(Analysis!$I4="","",IF(Analysis!$I4="Loyal but shallow",Analysis!$F4,"")) | K4: =IF(Analysis!$I4="","",IF(Analysis!$I4="Project-driven",Analysis!$F4,"")) | L4: =IF(Analysis!$I4="","",IF(Analysis!$I4="Drifting",Analysis!$F4,"")) -> 3.6666667 | M4: =IF(Analysis!$I4="","",IF(Analysis!$I4="Embedded",Analysis!$H4,"")) | N4: =IF(Analysis!$I4="","",IF(Analysis!$I4="Loyal but shallow",Analysis!$H4,"")) | O4: =IF(Analysis!$I4="","",IF(Analysis!$I4="Project-driven",Analysis!$H4,"")) | P4: =IF(Analysis!$I4="","",IF(Analysis!$I4="Drifting",Analysis!$H4,"")) -> 4
A5: =IF(Analysis!$I5="","",IF(Analysis!$I5="Embedded",Analysis!$D5,"")) | B5: =IF(Analysis!$I5="","",IF(Analysis!$I5="Loyal but shallow",Analysis!$D5,"")) | C5: =IF(Analysis!$I5="","",IF(Analysis!$I5="Project-driven",Analysis!$D5,"")) | D5: =IF(Analysis!$I5="","",IF(Analysis!$I5="Drifting",Analysis!$D5,"")) | E5: =IF(Analysis!$I5="","",IF(Analysis!$I5="Embedded",Analysis!$C5,"")) | F5: =IF(Analysis!$I5="","",IF(Analysis!$I5="Loyal but shallow",Analysis!$C5,"")) | G5: =IF(Analysis!$I5="","",IF(Analysis!$I5="Project-driven",Analysis!$C5,"")) | H5: =IF(Analysis!$I5="","",IF(Analysis!$I5="Drifting",Analysis!$C5,"")) | I5: =IF(Analysis!$I5="","",IF(Analysis!$I5="Embedded",Analysis!$F5,"")) | J5: =IF(Analysis!$I5="","",IF(Analysis!$I5="Loyal but shallow",Analysis!$F5,"")) | K5: =IF(Analysis!$I5="","",IF(Analysis!$I5="Project-driven",Analysis!$F5,"")) | L5: =IF(Analysis!$I5="","",IF(Analysis!$I5="Drifting",Analysis!$F5,"")) | M5: =IF(Analysis!$I5="","",IF(Analysis!$I5="Embedded",Analysis!$H5,"")) | N5: =IF(Analysis!$I5="","",IF(Analysis!$I5="Loyal but shallow",Analysis!$H5,"")) | O5: =IF(Analysis!$I5="","",IF(Analysis!$I5="Project-driven",Analysis!$H5,"")) | P5: =IF(Analysis!$I5="","",IF(Analysis!$I5="Drifting",Analysis!$H5,""))
A6: =IF(Analysis!$I6="","",IF(Analysis!$I6="Embedded",Analysis!$D6,"")) | B6: =IF(Analysis!$I6="","",IF(Analysis!$I6="Loyal but shallow",Analysis!$D6,"")) | C6: =IF(Analysis!$I6="","",IF(Analysis!$I6="Project-driven",Analysis!$D6,"")) | D6: =IF(Analysis!$I6="","",IF(Analysis!$I6="Drifting",Analysis!$D6,"")) | E6: =IF(Analysis!$I6="","",IF(Analysis!$I6="Embedded",Analysis!$C6,"")) | F6: =IF(Analysis!$I6="","",IF(Analysis!$I6="Loyal but shallow",Analysis!$C6,"")) | G6: =IF(Analysis!$I6="","",IF(Analysis!$I6="Project-driven",Analysis!$C6,"")) | H6: =IF(Analysis!$I6="","",IF(Analysis!$I6="Drifting",Analysis!$C6,"")) | I6: =IF(Analysis!$I6="","",IF(Analysis!$I6="Embedded",Analysis!$F6,"")) | J6: =IF(Analysis!$I6="","",IF(Analysis!$I6="Loyal but shallow",Analysis!$F6,"")) | K6: =IF(Analysis!$I6="","",IF(Analysis!$I6="Project-driven",Analysis!$F6,"")) | L6: =IF(Analysis!$I6="","",IF(Analysis!$I6="Drifting",Analysis!$F6,"")) | M6: =IF(Analysis!$I6="","",IF(Analysis!$I6="Embedded",Analysis!$H6,"")) | N6: =IF(Analysis!$I6="","",IF(Analysis!$I6="Loyal but shallow",Analysis!$H6,"")) | O6: =IF(Analysis!$I6="","",IF(Analysis!$I6="Project-driven",Analysis!$H6,"")) | P6: =IF(Analysis!$I6="","",IF(Analysis!$I6="Drifting",Analysis!$H6,""))
A7: =IF(Analysis!$I7="","",IF(Analysis!$I7="Embedded",Analysis!$D7,"")) | B7: =IF(Analysis!$I7="","",IF(Analysis!$I7="Loyal but shallow",Analysis!$D7,"")) | C7: =IF(Analysis!$I7="","",IF(Analysis!$I7="Project-driven",Analysis!$D7,"")) | D7: =IF(Analysis!$I7="","",IF(Analysis!$I7="Drifting",Analysis!$D7,"")) | E7: =IF(Analysis!$I7="","",IF(Analysis!$I7="Embedded",Analysis!$C7,"")) | F7: =IF(Analysis!$I7="","",IF(Analysis!$I7="Loyal but shallow",Analysis!$C7,"")) | G7: =IF(Analysis!$I7="","",IF(Analysis!$I7="Project-driven",Analysis!$C7,"")) | H7: =IF(Analysis!$I7="","",IF(Analysis!$I7="Drifting",Analysis!$C7,"")) | I7: =IF(Analysis!$I7="","",IF(Analysis!$I7="Embedded",Analysis!$F7,"")) | J7: =IF(Analysis!$I7="","",IF(Analysis!$I7="Loyal but shallow",Analysis!$F7,"")) | K7: =IF(Analysis!$I7="","",IF(Analysis!$I7="Project-driven",Analysis!$F7,"")) | L7: =IF(Analysis!$I7="","",IF(Analysis!$I7="Drifting",Analysis!$F7,"")) | M7: =IF(Analysis!$I7="","",IF(Analysis!$I7="Embedded",Analysis!$H7,"")) | N7: =IF(Analysis!$I7="","",IF(Analysis!$I7="Loyal but shallow",Analysis!$H7,"")) | O7: =IF(Analysis!$I7="","",IF(Analysis!$I7="Project-driven",Analysis!$H7,"")) | P7: =IF(Analysis!$I7="","",IF(Analysis!$I7="Drifting",Analysis!$H7,""))
A8: =IF(Analysis!$I8="","",IF(Analysis!$I8="Embedded",Analysis!$D8,"")) | B8: =IF(Analysis!$I8="","",IF(Analysis!$I8="Loyal but shallow",Analysis!$D8,"")) | C8: =IF(Analysis!$I8="","",IF(Analysis!$I8="Project-driven",Analysis!$D8,"")) | D8: =IF(Analysis!$I8="","",IF(Analysis!$I8="Drifting",Analysis!$D8,"")) | E8: =IF(Analysis!$I8="","",IF(Analysis!$I8="Embedded",Analysis!$C8,"")) | F8: =IF(Analysis!$I8="","",IF(Analysis!$I8="Loyal but shallow",Analysis!$C8,"")) | G8: =IF(Analysis!$I8="","",IF(Analysis!$I8="Project-driven",Analysis!$C8,"")) | H8: =IF(Analysis!$I8="","",IF(Analysis!$I8="Drifting",Analysis!$C8,"")) | I8: =IF(Analysis!$I8="","",IF(Analysis!$I8="Embedded",Analysis!$F8,"")) | J8: =IF(Analysis!$I8="","",IF(Analysis!$I8="Loyal but shallow",Analysis!$F8,"")) | K8: =IF(Analysis!$I8="","",IF(Analysis!$I8="Project-driven",Analysis!$F8,"")) | L8: =IF(Analysis!$I8="","",IF(Analysis!$I8="Drifting",Analysis!$F8,"")) | M8: =IF(Analysis!$I8="","",IF(Analysis!$I8="Embedded",Analysis!$H8,"")) | N8: =IF(Analysis!$I8="","",IF(Analysis!$I8="Loyal but shallow",Analysis!$H8,"")) | O8: =IF(Analysis!$I8="","",IF(Analysis!$I8="Project-driven",Analysis!$H8,"")) | P8: =IF(Analysis!$I8="","",IF(Analysis!$I8="Drifting",Analysis!$H8,""))
A9: =IF(Analysis!$I9="","",IF(Analysis!$I9="Embedded",Analysis!$D9,"")) | B9: =IF(Analysis!$I9="","",IF(Analysis!$I9="Loyal but shallow",Analysis!$D9,"")) | C9: =IF(Analysis!$I9="","",IF(Analysis!$I9="Project-driven",Analysis!$D9,"")) | D9: =IF(Analysis!$I9="","",IF(Analysis!$I9="Drifting",Analysis!$D9,"")) | E9: =IF(Analysis!$I9="","",IF(Analysis!$I9="Embedded",Analysis!$C9,"")) | F9: =IF(Analysis!$I9="","",IF(Analysis!$I9="Loyal but shallow",Analysis!$C9,"")) | G9: =IF(Analysis!$I9="","",IF(Analysis!$I9="Project-driven",Analysis!$C9,"")) | H9: =IF(Analysis!$I9="","",IF(Analysis!$I9="Drifting",Analysis!$C9,"")) | I9: =IF(Analysis!$I9="","",IF(Analysis!$I9="Embedded",Analysis!$F9,"")) | J9: =IF(Analysis!$I9="","",IF(Analysis!$I9="Loyal but shallow",Analysis!$F9,"")) | K9: =IF(Analysis!$I9="","",IF(Analysis!$I9="Project-driven",Analysis!$F9,"")) | L9: =IF(Analysis!$I9="","",IF(Analysis!$I9="Drifting",Analysis!$F9,"")) | M9: =IF(Analysis!$I9="","",IF(Analysis!$I9="Embedded",Analysis!$H9,"")) | N9: =IF(Analysis!$I9="","",IF(Analysis!$I9="Loyal but shallow",Analysis!$H9,"")) | O9: =IF(Analysis!$I9="","",IF(Analysis!$I9="Project-driven",Analysis!$H9,"")) | P9: =IF(Analysis!$I9="","",IF(Analysis!$I9="Drifting",Analysis!$H9,""))
A10: =IF(Analysis!$I10="","",IF(Analysis!$I10="Embedded",Analysis!$D10,"")) | B10: =IF(Analysis!$I10="","",IF(Analysis!$I10="Loyal but shallow",Analysis!$D10,"")) | C10: =IF(Analysis!$I10="","",IF(Analysis!$I10="Project-driven",Analysis!$D10,"")) | D10: =IF(Analysis!$I10="","",IF(Analysis!$I10="Drifting",Analysis!$D10,"")) | E10: =IF(Analysis!$I10="","",IF(Analysis!$I10="Embedded",Analysis!$C10,"")) | F10: =IF(Analysis!$I10="","",IF(Analysis!$I10="Loyal but shallow",Analysis!$C10,"")) | G10: =IF(Analysis!$I10="","",IF(Analysis!$I10="Project-driven",Analysis!$C10,"")) | H10: =IF(Analysis!$I10="","",IF(Analysis!$I10="Drifting",Analysis!$C10,"")) | I10: =IF(Analysis!$I10="","",IF(Analysis!$I10="Embedded",Analysis!$F10,"")) | J10: =IF(Analysis!$I10="","",IF(Analysis!$I10="Loyal but shallow",Analysis!$F10,"")) | K10: =IF(Analysis!$I10="","",IF(Analysis!$I10="Project-driven",Analysis!$F10,"")) | L10: =IF(Analysis!$I10="","",IF(Analysis!$I10="Drifting",Analysis!$F10,"")) | M10: =IF(Analysis!$I10="","",IF(Analysis!$I10="Embedded",Analysis!$H10,"")) | N10: =IF(Analysis!$I10="","",IF(Analysis!$I10="Loyal but shallow",Analysis!$H10,"")) | O10: =IF(Analysis!$I10="","",IF(Analysis!$I10="Project-driven",Analysis!$H10,"")) | P10: =IF(Analysis!$I10="","",IF(Analysis!$I10="Drifting",Analysis!$H10,""))
A11: =IF(Analysis!$I11="","",IF(Analysis!$I11="Embedded",Analysis!$D11,"")) | B11: =IF(Analysis!$I11="","",IF(Analysis!$I11="Loyal but shallow",Analysis!$D11,"")) | C11: =IF(Analysis!$I11="","",IF(Analysis!$I11="Project-driven",Analysis!$D11,"")) | D11: =IF(Analysis!$I11="","",IF(Analysis!$I11="Drifting",Analysis!$D11,"")) | E11: =IF(Analysis!$I11="","",IF(Analysis!$I11="Embedded",Analysis!$C11,"")) | F11: =IF(Analysis!$I11="","",IF(Analysis!$I11="Loyal but shallow",Analysis!$C11,"")) | G11: =IF(Analysis!$I11="","",IF(Analysis!$I11="Project-driven",Analysis!$C11,"")) | H11: =IF(Analysis!$I11="","",IF(Analysis!$I11="Drifting",Analysis!$C11,"")) | I11: =IF(Analysis!$I11="","",IF(Analysis!$I11="Embedded",Analysis!$F11,"")) | J11: =IF(Analysis!$I11="","",IF(Analysis!$I11="Loyal but shallow",Analysis!$F11,"")) | K11: =IF(Analysis!$I11="","",IF(Analysis!$I11="Project-driven",Analysis!$F11,"")) | L11: =IF(Analysis!$I11="","",IF(Analysis!$I11="Drifting",Analysis!$F11,"")) | M11: =IF(Analysis!$I11="","",IF(Analysis!$I11="Embedded",Analysis!$H11,"")) | N11: =IF(Analysis!$I11="","",IF(Analysis!$I11="Loyal but shallow",Analysis!$H11,"")) | O11: =IF(Analysis!$I11="","",IF(Analysis!$I11="Project-driven",Analysis!$H11,"")) | P11: =IF(Analysis!$I11="","",IF(Analysis!$I11="Drifting",Analysis!$H11,""))
A12: =IF(Analysis!$I12="","",IF(Analysis!$I12="Embedded",Analysis!$D12,"")) | B12: =IF(Analysis!$I12="","",IF(Analysis!$I12="Loyal but shallow",Analysis!$D12,"")) | C12: =IF(Analysis!$I12="","",IF(Analysis!$I12="Project-driven",Analysis!$D12,"")) | D12: =IF(Analysis!$I12="","",IF(Analysis!$I12="Drifting",Analysis!$D12,"")) | E12: =IF(Analysis!$I12="","",IF(Analysis!$I12="Embedded",Analysis!$C12,"")) | F12: =IF(Analysis!$I12="","",IF(Analysis!$I12="Loyal but shallow",Analysis!$C12,"")) | G12: =IF(Analysis!$I12="","",IF(Analysis!$I12="Project-driven",Analysis!$C12,"")) | H12: =IF(Analysis!$I12="","",IF(Analysis!$I12="Drifting",Analysis!$C12,"")) | I12: =IF(Analysis!$I12="","",IF(Analysis!$I12="Embedded",Analysis!$F12,"")) | J12: =IF(Analysis!$I12="","",IF(Analysis!$I12="Loyal but shallow",Analysis!$F12,"")) | K12: =IF(Analysis!$I12="","",IF(Analysis!$I12="Project-driven",Analysis!$F12,"")) | L12: =IF(Analysis!$I12="","",IF(Analysis!$I12="Drifting",Analysis!$F12,"")) | M12: =IF(Analysis!$I12="","",IF(Analysis!$I12="Embedded",Analysis!$H12,"")) | N12: =IF(Analysis!$I12="","",IF(Analysis!$I12="Loyal but shallow",Analysis!$H12,"")) | O12: =IF(Analysis!$I12="","",IF(Analysis!$I12="Project-driven",Analysis!$H12,"")) | P12: =IF(Analysis!$I12="","",IF(Analysis!$I12="Drifting",Analysis!$H12,""))
A13: =IF(Analysis!$I13="","",IF(Analysis!$I13="Embedded",Analysis!$D13,"")) | B13: =IF(Analysis!$I13="","",IF(Analysis!$I13="Loyal but shallow",Analysis!$D13,"")) | C13: =IF(Analysis!$I13="","",IF(Analysis!$I13="Project-driven",Analysis!$D13,"")) | D13: =IF(Analysis!$I13="","",IF(Analysis!$I13="Drifting",Analysis!$D13,"")) | E13: =IF(Analysis!$I13="","",IF(Analysis!$I13="Embedded",Analysis!$C13,"")) | F13: =IF(Analysis!$I13="","",IF(Analysis!$I13="Loyal but shallow",Analysis!$C13,"")) | G13: =IF(Analysis!$I13="","",IF(Analysis!$I13="Project-driven",Analysis!$C13,"")) | H13: =IF(Analysis!$I13="","",IF(Analysis!$I13="Drifting",Analysis!$C13,"")) | I13: =IF(Analysis!$I13="","",IF(Analysis!$I13="Embedded",Analysis!$F13,"")) | J13: =IF(Analysis!$I13="","",IF(Analysis!$I13="Loyal but shallow",Analysis!$F13,"")) | K13: =IF(Analysis!$I13="","",IF(Analysis!$I13="Project-driven",Analysis!$F13,"")) | L13: =IF(Analysis!$I13="","",IF(Analysis!$I13="Drifting",Analysis!$F13,"")) | M13: =IF(Analysis!$I13="","",IF(Analysis!$I13="Embedded",Analysis!$H13,"")) | N13: =IF(Analysis!$I13="","",IF(Analysis!$I13="Loyal but shallow",Analysis!$H13,"")) | O13: =IF(Analysis!$I13="","",IF(Analysis!$I13="Project-driven",Analysis!$H13,"")) | P13: =IF(Analysis!$I13="","",IF(Analysis!$I13="Drifting",Analysis!$H13,""))
... A1001: =IF(Analysis!$I1001="","",IF(Analysis!$I1001="Embedded",Analysis!$D1001,"")) | B1001: =IF(Analysis!$I1001="","",IF(Analysis!$I1001="Loyal but shallow",Analysis!$D1001,"")) | C1001: =IF(Analysis!$I1001="","",IF(Analysis!$I1001="Project-driven",Analysis!$D1001,"")) | D1001: =IF(Analysis!$I1001="","",IF(Analysis!$I1001="Drifting",Analysis!$D1001,"")) | E1001: =IF(Analysis!$I1001="","",IF(Analysis!$I1001="Embedded",Analysis!$C1001,"")) | F1001: =IF(Analysis!$I1001="","",IF(Analysis!$I1001="Loyal but shallow",Analysis!$C1001,"")) | G1001: =IF(Analysis!$I1001="","",IF(Analysis!$I1001="Project-driven",Analysis!$C1001,"")) | H1001: =IF(Analysis!$I1001="","",IF(Analysis!$I1001="Drifting",Analysis!$C1001,"")) | I1001: =IF(Analysis!$I1001="","",IF(Analysis!$I1001="Embedded",Analysis!$F1001,"")) | J1001: =IF(Analysis!$I1001="","",IF(Analysis!$I1001="Loyal but shallow",Analysis!$F1001,"")) | K1001: =IF(Analysis!$I1001="","",IF(Analysis!$I1001="Project-driven",Analysis!$F1001,"")) | L1001: =IF(Analysis!$I1001="","",IF(Analysis!$I1001="Drifting",Analysis!$F1001,"")) | M1001: =IF(Analysis!$I1001="","",IF(Analysis!$I1001="Embedded",Analysis!$H1001,"")) | N1001: =IF(Analysis!$I1001="","",IF(Analysis!$I1001="Loyal but shallow",Analysis!$H1001,"")) | O1001: =IF(Analysis!$I1001="","",IF(Analysis!$I1001="Project-driven",Analysis!$H1001,"")) | P1001: =IF(Analysis!$I1001="","",IF(Analysis!$I1001="Drifting",Analysis!$H1001,""))

Sheet Segments
A1: Segments
A2: =cust_name&" - "&nrows&" users - "&period_days&"-day window - refreshed "&IF(refresh_date="","date not stated",TEXT(refresh_date,"d mmm yyyy"))&" - "&run_mode&" mode" -> Example Customer Ltd - 3 users - 90-day window - refreshed 26 Aug 2026 - SMALL mode
A3: Relationships shown are correlational. This measures where the tool has not been made useful yet - not effort, contribution or value.
A5: Band | B5: Threshold rule | C5: Users | D5: % of users | E5: % of all prompts | F5: Median prompts | G5: Median active days | H5: Median prompts / active day | I5: Median surfaces | J5: What it means
A6: Embedded | B6: Active days >= frequency line AND prompts >= depth line | C6: =COUNTIF(Analysis!$I$2:$I$1001,$A6) -> 1 | D6: =IF($C6<5,"n<5 not reported",IFERROR($C6/nrows,0)) -> n<5 not reported | E6: =IF($C6<5,"n<5 not reported",IFERROR(SUMIF(Analysis!$I$2:$I$1001,$A6,Analysis!$D$2:$D$1001)/SUM(Analysis!$D$2:$D$1001),0)) -> n<5 not reported | F6: =IF($C6<5,"n<5 not reported",MEDIAN(Calc!$A$2:$A$1001)) -> n<5 not reported | G6: =IF($C6<5,"n<5 not reported",MEDIAN(Calc!$E$2:$E$1001)) -> n<5 not reported | H6: =IF($C6<5,"n<5 not reported",MEDIAN(Calc!$I$2:$I$1001)) -> n<5 not reported | I6: =IF($C6<5,"n<5 not reported",MEDIAN(Calc!$M$2:$M$1001)) -> n<5 not reported | J6: Frequent and deep. This is where the return is concentrated, and it is usually thinner than anyone expects. Check agent access before anyone proposes building agents.
A7: Loyal but shallow | B7: Active days >= frequency line AND prompts < depth line | C7: =COUNTIF(Analysis!$I$2:$I$1001,$A7) -> 1 | D7: =IF($C7<5,"n<5 not reported",IFERROR($C7/nrows,0)) -> n<5 not reported | E7: =IF($C7<5,"n<5 not reported",IFERROR(SUMIF(Analysis!$I$2:$I$1001,$A7,Analysis!$D$2:$D$1001)/SUM(Analysis!$D$2:$D$1001),0)) -> n<5 not reported | F7: =IF($C7<5,"n<5 not reported",MEDIAN(Calc!$B$2:$B$1001)) -> n<5 not reported | G7: =IF($C7<5,"n<5 not reported",MEDIAN(Calc!$F$2:$F$1001)) -> n<5 not reported | H7: =IF($C7<5,"n<5 not reported",MEDIAN(Calc!$J$2:$J$1001)) -> n<5 not reported | I7: =IF($C7<5,"n<5 not reported",MEDIAN(Calc!$N$2:$N$1001)) -> n<5 not reported | J7: Present more often than the threshold, running a low rate per active day. Months of loyalty to a single use case. The highest conversion rate you will find: sell a second use case, not a mindset.
A8: Project-driven | B8: Active days < frequency line AND prompts >= depth line | C8: =COUNTIF(Analysis!$I$2:$I$1001,$A8) -> 0 | D8: =IF($C8<5,"n<5 not reported",IFERROR($C8/nrows,0)) -> n<5 not reported | E8: =IF($C8<5,"n<5 not reported",IFERROR(SUMIF(Analysis!$I$2:$I$1001,$A8,Analysis!$D$2:$D$1001)/SUM(Analysis!$D$2:$D$1001),0)) -> n<5 not reported | F8: =IF($C8<5,"n<5 not reported",MEDIAN(Calc!$C$2:$C$1001)) -> n<5 not reported | G8: =IF($C8<5,"n<5 not reported",MEDIAN(Calc!$G$2:$G$1001)) -> n<5 not reported | H8: =IF($C8<5,"n<5 not reported",MEDIAN(Calc!$K$2:$K$1001)) -> n<5 not reported | I8: =IF($C8<5,"n<5 not reported",MEDIAN(Calc!$O$2:$O$1001)) -> n<5 not reported | J8: Rare visits, deep sessions. Capable and not yet embedded in anything weekly. Workflow embedding, and check their grounding -- this band skews to ungrounded chat.
A9: Drifting | B9: Active days < frequency line AND prompts < depth line | C9: =COUNTIF(Analysis!$I$2:$I$1001,$A9) -> 1 | D9: =IF($C9<5,"n<5 not reported",IFERROR($C9/nrows,0)) -> n<5 not reported | E9: =IF($C9<5,"n<5 not reported",IFERROR(SUMIF(Analysis!$I$2:$I$1001,$A9,Analysis!$D$2:$D$1001)/SUM(Analysis!$D$2:$D$1001),0)) -> n<5 not reported | F9: =IF($C9<5,"n<5 not reported",MEDIAN(Calc!$D$2:$D$1001)) -> n<5 not reported | G9: =IF($C9<5,"n<5 not reported",MEDIAN(Calc!$H$2:$H$1001)) -> n<5 not reported | H9: =IF($C9<5,"n<5 not reported",MEDIAN(Calc!$L$2:$L$1001)) -> n<5 not reported | I9: =IF($C9<5,"n<5 not reported",MEDIAN(Calc!$P$2:$P$1001)) -> n<5 not reported | J9: Fails both lines. Split it before you act on it: people who tried several surfaces and stopped are recoverable with use-case design; people who never started may be a licensing error.
A10: All bands | B10: Should equal the rows detected on Setup. | C10: =SUM(C6:C9) -> 3 | D10: =IF(nrows=0,"",SUM(C6:C9)/nrows) -> 1 | E10: =IF(SUM(Analysis!$D$2:$D$1001)=0,"",1) -> 1
A12: The finding
A13: =IF($C$6<5,"Fewer than five Embedded users - do not quote a share. Report the count ("&$C$6&") and the never-active number instead, and say plainly that the sample is too small for a percentage.","Embedded users are "&TEXT($D$6,"0.0%")&" of the licensed population and generate "&TEXT($E$6,"0.0%")&" of all prompts. That gap is the finding: it is where the return is concentrated, and how thin it is.") -> Fewer than five Embedded users - do not quote a share. Report the count (1) and the never-active number instead, and say plainly that the sample is too small for a percentage.
A14: =IF($C$9<5,"Fewer than five Drifting users - report the count ("&$C$9&") only.","Drifting users are "&TEXT($D$9,"0.0%")&" of the population and generate "&TEXT($E$9,"0.0%")&" of all prompts. Exposure happened; a reason to come back did not. Split the band below before acting on it.") -> Fewer than five Drifting users - report the count (1) only.
A16: Licence exposure - four numbers, and they are never merged
A17: Never active (zero prompts and zero active days) | C17: =SUM(Analysis!$L$2:$L$1001) -> 0
A18: Zero prompts (excluded from the chart) | C18: =COUNTIF(Analysis!$D$2:$D$1001,0) -> 0
A19: Drifting - never started (under 3 surfaces touched) | C19: =COUNTIF(Analysis!$J$2:$J$1001,"never started") -> 0
A20: Drifting - tried and stopped (3 or more surfaces touched) | C20: =COUNTIF(Analysis!$J$2:$J$1001,"tried and stopped") -> 1
A21: These four overlap and they are not a wasted-licence total. Do not add them together and do not put a single number on a slide. Reconcile the row count against currently assigned licences under Billing > Licenses first: the table shows everyone who held a Copilot licence at any point in the window, including people whose licence was removed.
A23: The realistic ceiling - prompts per active day, in this tenant
A24: Median | C24: =IF(nrows=0,0,PERCENTILE(Analysis!$F$2:$F$1001,0.5)) -> 3.6666667
A25: 75th percentile | C25: =IF(nrows=0,0,PERCENTILE(Analysis!$F$2:$F$1001,0.75)) -> 8.3439716
A26: 95th percentile | C26: =IF(nrows=0,0,PERCENTILE(Analysis!$F$2:$F$1001,0.95)) -> 12.085816
A27: Maximum | C27: =MAX(Analysis!$F$2:$F$1001) -> 13.021277
A28: =IF(nrows<60,"Under 60 users - quote the median and the maximum only. A 75th or 95th percentile computed on this few people is one person, and someone in the room will work out who.","Use these to replace an invented adoption target with a defensible one drawn from this tenant's own distribution.") -> Under 60 users - quote the median and the maximum only. A 75th or 95th percentile computed on this few people is one person, and someone in the room will work out who.

Sheet Chart
A1: Frequency against depth
A2: =IF(run_mode="SMALL","SMALL MODE - do not use this chart. Read the ranked list on Analysis instead.","") -> SMALL MODE - do not use this chart. Read the ranked list on Analysis instead.
A3: ="Excluded from the plot: "&COUNTIF(Analysis!$D$2:$D$1001,0)&" users with zero prompts (a logarithmic axis cannot render zero; they are plotted at 1). Report refreshed "&IF(refresh_date="","date not stated",TEXT(refresh_date,"d mmm yyyy"))&", "&period_days&"-day window, "&nrows&" users. Relationships shown are correlational - this is a map of unrealised opportunity, not a scorecard of outcome." -> Excluded from the plot: 0 users with zero prompts (a logarithmic axis cannot render zero; they are plotted at 1). Report refreshed 26 Aug 2026, 90-day window, 3 users. Relationships shown are correlational - this is a map of unrealised opportunity, not a scorecard of outcome.
A34: Every point is one user. Horizontal position is how often they used Copilot Chat; vertical position is how much. The two threshold lines are on Setup - change them there and the whole population re-sorts.

Sheet Book Ranking
A1: Book ranking - one row per Copilot customer
A2: Row 5 reads this workbook's own result in green. Rows 6 and below are yellow: one row per customer, filled in from that customer's copy of this workbook. Sort by never-active share descending and filter to renewals inside two quarters, and you have your priority list.
A4: Customer | B4: Licensed users | C4: Never active | D4: Never active % | E4: Drifting % | F4: Embedded % | G4: Embedded with no agent use | H4: Web-only users | I4: Months to renewal | J4: Next play | K4: Owner | L4: Date agreed
A5: =cust_name -> Example Customer Ltd | B5: =nrows -> 3 | C5: =SUM(Analysis!$L$2:$L$1001) -> 0 | D5: =IFERROR(C5/B5,0) -> 0 | E5: =Segments!$D$9 -> n<5 not reported | F5: =Segments!$D$6 -> n<5 not reported | H5: =COUNTIF(Analysis!$G$2:$G$1001,">=0.9") -> 0 | N5: G comes from the agents usage report, not from this export - the two reports do not share a window, so state both. I to L come from your own systems.
A27: Next play - one of four: use-case design by job role (Drifting), a second use case in thirty minutes (Loyal but shallow), workflow embedding plus a grounding conversation (Project-driven), agent access rather than agent authorship (Embedded). Assign an owner and a date or the exercise stays interesting and never becomes revenue.
A29: Rows are only comparable if they were produced in the same mode. The mode is stamped on each workbook's Segments subtitle - record it if you mix tenant sizes.

Sheet Reference
B2: Reference
B3: The offline twin of Sections 8, 9 and 13 of the Copilot Adoption Audit page. Microsoft's reporting surface changes frequently - re-verify column names, report paths and window lengths before you re-deliver.
B5: The five reports
B6: Microsoft Copilot usage report - user-level table
B7: Portal | C7: Microsoft 365 admin center - admin.microsoft.com
B8: Navigation | C8: Reports > Usage > Microsoft Copilot > Copilot > the Usage tab. If Reports is not in the navigation menu, choose Show all first.
B9: Period | C9: 7 / 28 / 90 / 180 days. Take 180 for a full read, or 90 if you are working at small-tenant thresholds. Do not use 7 or 28.
B10: Role | C10: Reports Reader, or any of: Usage Summary Reports Reader, AI Administrator, Exchange / SharePoint / Teams / Teams Communications Administrator, User Experience Success Manager, Global Administrator.
B11: What you take | C11: Scroll to the user-level table, choose Choose columns and switch on everything, then use the Export on the table. The ellipsis Export on each chart gives you the chart's aggregate, not the user detail.
B13: Microsoft Copilot agents usage report
B14: Portal | C14: Microsoft 365 admin center - admin.microsoft.com
B15: Navigation | C15: Reports > Usage > Microsoft Copilot > Agents
B16: Period | C16: 7 or 30 days only. Not 90, not 180.
B17: Role | C17: Same roles as the usage report. Names are concealed here too.
B18: What you take | C18: Three tables: user details, agent details, and a user-and-agent pair view. The pair view tells you whether your champions have ever been given an agent.
B20: Microsoft Copilot readiness report
B21: Portal | C21: Microsoft 365 admin center - admin.microsoft.com
B22: Navigation | C22: Reports > Usage > Microsoft Copilot > Readiness
B23: Period | C23: Snapshot of eligibility and assignment rather than a rolling window.
B24: Role | C24: Same roles as the usage report.
B25: What you take | C25: Who is eligible, who is licensed, where the gaps are. Use it when the tenant is not far enough along to have a distribution worth plotting.
B27: Microsoft Copilot Dashboard - Viva Insights
B28: Portal | C28: Microsoft Viva Insights. Quickest route in is the Recommendations card inside the Copilot usage report.
B29: Navigation | C29: Viva Insights > Copilot Dashboard
B30: Period | C30: Rolling windows set by the dashboard. Processing starts once at least one Copilot licence is assigned and takes up to seven days.
B31: Role | C31: Available with one or more Copilot licences. No paid Viva Insights licence required to view.
